<?xml version="1.0" ?>
<!-- =================================================================================== -->
<!-- |    This document was autogenerated by xacro from wheebbot.urdf.xacro            | -->
<!-- |    EDITING THIS FILE BY HAND IS NOT RECOMMENDED                                 | -->
<!-- =================================================================================== -->
<robot name="wheebbot">
  <!-- Reading some parameters from a YAML config file -->
  <!-- Assigning those parameters to xacro properties -->
  <material name="black">
    <color rgba="0.0 0.0 0.0 1.0"/>
  </material>
  <material name="blue">
    <color rgba="0.0 0.0 0.8 1.0"/>
  </material>
  <material name="green">
    <color rgba="0.0 0.8 0.0 1.0"/>
  </material>
  <material name="grey">
    <color rgba="0.2 0.2 0.2 1.0"/>
  </material>
  <material name="orange">
    <color rgba="1.0 0.4235294117647059 0.0392156862745098 1.0"/>
  </material>
  <material name="brown">
    <color rgba="0.8705882352941177 0.8117647058823529 0.7647058823529411 1.0"/>
  </material>
  <material name="red">
    <color rgba="0.8 0.0 0.0 1.0"/>
  </material>
  <material name="white">
    <color rgba="1.0 1.0 1.0 1.0"/>
  </material>
  <!-- ros_control plugin -->
  <gazebo>
    <plugin filename="libgazebo_ros_joint_state_publisher.so" name="gazebo_ros_joint_state_publisher">
      <update_rate>20</update_rate>
      <joint_name>left_wheel_joint</joint_name>
      <joint_name>right_wheel_joint</joint_name>
    </plugin>
  </gazebo>
  <!-- right wheel -->
  <gazebo reference="right_wheel">
    <mu1>0.5</mu1>
    <mu2>0.5</mu2>
  </gazebo>
  <!-- left wheel -->
  <gazebo reference="left_wheel">
    <mu1>0.5</mu1>
    <mu2>0.5</mu2>
  </gazebo>
  <link name="base_link">
  </link>
  <link name="body">
    <!-- body visual -->
    <visual>
      <origin rpy="0 0 -1.5707963267948966" xyz="0 0.095 -0.07"/>
      <geometry>
        <mesh filename="package://wheebbot/description/meshes/full_no_knee_no_wheels.dae" scale="1.0 1.0 1.0"/>
      </geometry>
    </visual>
    <!-- box -->
    <collision>
      <origin rpy="0 0 0" xyz="0 0 0"/>
      <geometry>
        <box size="0.16 0.21 0.16"/>
      </geometry>
    </collision>
    <!-- top fan collision group-->
    <!-- fan-->
    <collision>
      <origin rpy="0 0 0" xyz="0 0 0.0983"/>
      <geometry>
        <box size="0.12 0.12 0.0366"/>
      </geometry>
    </collision>
    <!-- left door handle-->
    <collision>
      <origin rpy="0 0 0" xyz="0 0.095 0.0875"/>
      <geometry>
        <box size="0.105 0.02 0.015"/>
      </geometry>
    </collision>
    <collision>
      <origin rpy="0 0 0" xyz="0 0.095 0.106"/>
      <geometry>
        <box size="0.075 0.02 0.022"/>
      </geometry>
    </collision>
    <!-- right door handle-->
    <collision>
      <origin rpy="0 0 0" xyz="0 -0.095 0.0875"/>
      <geometry>
        <box size="0.105 0.02 0.015"/>
      </geometry>
    </collision>
    <collision>
      <origin rpy="0 0 0" xyz="0 -0.095 0.106"/>
      <geometry>
        <box size="0.075 0.02 0.022"/>
      </geometry>
    </collision>
    <!-- back fan collision -->
    <collision>
      <origin rpy="0 -1.5707963267948966 0" xyz="-0.0983 0 0"/>
      <geometry>
        <box size="0.12 0.12 0.0366"/>
      </geometry>
    </collision>
    <!-- left leg -->
    <collision>
      <origin rpy="0 0 0" xyz="-0.0040000000000000036 0.095 -0.21500000000000002"/>
      <geometry>
        <box size="0.02 0.02 0.27"/>
      </geometry>
    </collision>
    <!-- left motor case -->
    <collision>
      <origin rpy="0 0 0" xyz="-0.0040000000000000036 0.0675 -0.37800000000000006"/>
      <geometry>
        <box size="0.056 0.075 0.056"/>
      </geometry>
    </collision>
    <!-- right leg -->
    <collision>
      <origin rpy="0 0 0" xyz="-0.0040000000000000036 -0.095 -0.21500000000000002"/>
      <geometry>
        <box size="0.02 0.02 0.27"/>
      </geometry>
    </collision>
    <!-- right motor case -->
    <collision>
      <origin rpy="0 0 0" xyz="-0.0040000000000000036 -0.0675 -0.37800000000000006"/>
      <geometry>
        <box size="0.056 0.075 0.056"/>
      </geometry>
    </collision>
    <inertial>
      <origin rpy="0 0.0 0" xyz="0.0 0 -0.17800000000000005"/>
      <mass value="5.0"/>
      <inertia ixx="0.020833333333333336" ixy="0.0" ixz="0.0" iyy="0.020833333333333336" iyz="0.0" izz="0.008333333333333335"/>
    </inertial>
  </link>
  <link name="left_wheel">
    <!-- wheel visual -->
    <visual>
      <origin rpy="0 0 1.5707963267948966" xyz="0 0 0"/>
      <geometry>
        <mesh filename="package://wheebbot/description/meshes/wheel_full.dae" scale="1.0 1.0 1.0"/>
      </geometry>
    </visual>
    <collision>
      <origin rpy="1.5707963267948966 0 0" xyz="0 0 0"/>
      <geometry>
        <cylinder length="0.02" radius="0.06"/>
      </geometry>
    </collision>
    <inertial>
      <origin rpy="-1.5707963267948966 0 0" xyz="0 0 0"/>
      <mass value="0.6"/>
      <inertia ixx="0.0005599999999999998" ixy="0.0" ixz="0.0" iyy="0.0005599999999999998" iyz="0.0" izz="0.00108"/>
    </inertial>
  </link>
  <link name="right_wheel">
    <!-- wheel visual -->
    <visual>
      <origin rpy="0 0 -1.5707963267948966" xyz="0 0 0"/>
      <geometry>
        <mesh filename="package://wheebbot/description/meshes/wheel_full.dae" scale="1.0 1.0 1.0"/>
      </geometry>
    </visual>
    <collision>
      <origin rpy="1.5707963267948966 0 0" xyz="0 0 0"/>
      <geometry>
        <cylinder length="0.02" radius="0.06"/>
      </geometry>
    </collision>
    <inertial>
      <origin rpy="-1.5707963267948966 0 0" xyz="0 0 0"/>
      <mass value="0.6"/>
      <inertia ixx="0.0005599999999999998" ixy="0.0" ixz="0.0" iyy="0.0005599999999999998" iyz="0.0" izz="0.00108"/>
    </inertial>
  </link>
  <joint name="floating_base_joint" type="fixed">
    <origin rpy="0 0 0" xyz="0 0 0"/>
    <parent link="base_link"/>
    <child link="body"/>
  </joint>
  <joint name="left_wheel_joint" type="continuous">
    <origin rpy="0 0 0" xyz="0 0.14 -0.37800000000000006"/>
    <parent link="body"/>
    <child link="left_wheel"/>
    <axis xyz="0 1 0"/>
    <dynamics damping="0.0" friction="0.0"/>
    <limit effort="30" velocity="100.0"/>
  </joint>
  <joint name="right_wheel_joint" type="continuous">
    <origin rpy="0 0 0" xyz="0 -0.14 -0.37800000000000006"/>
    <parent link="body"/>
    <child link="right_wheel"/>
    <axis xyz="0 1 0"/>
    <dynamics damping="0.0" friction="0.0"/>
    <limit effort="30" velocity="100.0"/>
  </joint>
</robot>
